/**
 * Tests for async/await standardization improvements
 */
import { describe, it, expect, vi } from 'vitest';

describe('Async/Await Standardization', () => {
  it('should use async/await pattern instead of promise chains for error handling', () => {
    // Test that we can handle async operations with try/catch instead of .catch()
    const mockAsyncOperation = vi.fn().mockRejectedValue(new Error('Test error'));

    const handleWithAsyncAwait = async () => {
      try {
        await mockAsyncOperation();
        return { success: true };
      } catch (error) {
        const err = error instanceof Error ? error : new Error(String(error));
        return { success: false, error: err.message };
      }
    };

    expect(handleWithAsyncAwait()).resolves.toEqual({
      success: false,
      error: 'Test error',
    });
  });

  it('should handle constructor async operations with proper error handling', async () => {
    // Test the pattern used in controllers where async operations are called from constructor
    const mockInitialize = vi.fn().mockRejectedValue(new Error('Init failed'));

    const createAsyncInitWrapper = (initFn: () => Promise<void>) => {
      const initializeAsync = async () => {
        try {
          await initFn();
          return { success: true };
        } catch (error) {
          const err = error instanceof Error ? error : new Error(String(error));
          return { success: false, error: err.message };
        }
      };

      return initializeAsync;
    };

    const wrapper = createAsyncInitWrapper(mockInitialize);
    const result = await wrapper();

    expect(result).toEqual({
      success: false,
      error: 'Init failed',
    });
  });
});
